<?xml version="1.0"?>
<robot name="flintrobot"> 
  <link name="base_link">
    <collision>
      <geometry>
        <cylinder length="0.34" radius="0.12"/>
      </geometry>
      <origin rpy="1.57075 0 0" xyz="0 0 0.12"/>
    </collision>
  </link>
  
  <link name="wheel_link">
    <visual>
      <geometry>
        <mesh filename="package://flintrobot_description/meshes/flint_wheel1.stl"/>
      </geometry>
    </visual>
  </link>

  <joint name="wheel1_to_base" type="fixed">
    <axis xyz="0 0 0"/>
    <origin xyz="0 0.171517 0.121921"/>
    <parent link="base_link"/>
    <child link="wheel_link"/>
  </joint>

  <link name="wheel_link2">
    <visual>
      <geometry>
        <mesh filename="package://flintrobot_description/meshes/flint_wheel1.stl"/>
      </geometry>
    </visual>
  </link>

  <joint name="wheel2_to_base" type="fixed">
    <axis xyz="0 0 0"/>
    <origin xyz="0 -0.171517 0.121921" rpy="0 0 3.1416"/>
    <parent link="base_link"/>
    <child link="wheel_link2"/>
  </joint>

  <link name="body_link">
    <visual>
      <geometry>
        <mesh filename="package://flintrobot_description/meshes/flint_body.stl"/>
      </geometry>
    </visual>
    <collision>
      <geometry>
        <cylinder length="0.9" radius="0.15"/>
      </geometry>
      <origin rpy="0 0 0" xyz="0 0 0.5352"/>
    </collision>
  </link>

  <joint name="robot_roll_angle" type="fixed">
    <axis xyz="0 1 0"/>
    <origin xyz="0 0 0.16"/>
    <parent link="base_link"/>
    <child link="body_link"/>
    <limit effort="1000" lower="-0.2618" upper="0.2618" velocity="1.0"/>
  </joint>

  <link name="imu_link">
    <visual>
      <geometry>
        <box size="0.03 0.02 0.002"/>
      </geometry>
      <material name="green">
        <color rgba="0.0 1.0 0.0 1.0"/>
      </material>
    </visual>
  </link>

  <joint name="imu_to_body" type="fixed">
    <axis xyz="0 0 1"/>
    <origin xyz="0 0 0" rpy="0 0 1.5708"/>
    <parent link="body_link"/>
    <child link="imu_link"/>
  </joint>

  <link name="rslidar">
    <visual>
      <geometry>
        <box size="0.02 0.03 0.05"/>
      </geometry>
      <material name="green">
        <color rgba="0.0 1.0 0.0 1.0"/>
      </material>
      <origin rpy="0 0 0" xyz="0 0 0"/>
    </visual>
  </link>

  <joint name="laser_to_body" type="fixed">
    <origin xyz="0.15475 0 0.77"/>
    <parent link="body_link"/>
    <child link="rslidar"/>
  </joint>

  <link name="head_base_root"/>

  <joint name="head_base_root_joint" type="fixed">
    <origin rpy="0 0 0" xyz="0.01385 0 0.9417"/>
    <parent link="body_link"/>
    <child link="head_base_root"/>
  </joint>

  <link name="head_base_raise_joint_x">
    <inertial>
      <mass value="1.0" />
      <inertia ixx="0.5" ixy="0.0" ixz="0.0" iyy="0.5" iyz="0.0" izz="0.5" />
    </inertial>
  </link>

  <joint name="head_base_raise_joint_x" type="prismatic">
    <origin rpy="0 0 0" xyz="0 0 0"/>
    <axis xyz="1 0 0"/>
    <limit effort="1000" lower="0.0" upper="0.07044" velocity="0.1"/>
    <parent link="head_base_root"/>
    <child link="head_base_raise_joint_x"/>
  </joint>

  <link name="head_base_raise_joint_z">
    <inertial>
      <mass value="1.0" />
      <inertia ixx="0.5" ixy="0.0" ixz="0.0" iyy="0.5" iyz="0.0" izz="0.5" />
    </inertial>
  </link>

  <joint name="head_base_raise_joint_z" type="prismatic">
    <origin rpy="0 0 0" xyz="0 0 0"/>
    <axis xyz="0 0 1"/>
    <limit effort="1000" lower="0.0" upper="0.03792" velocity="0.1"/>
    <parent link="head_base_raise_joint_x"/>
    <child link="head_base_raise_joint_z"/>
  </joint>

  <link name="head_base_raise_joint_pitch">
    <visual>
      <geometry>
        <mesh filename="package://flintrobot_description/meshes/flint_neck0.stl"/>
      </geometry>
    </visual>
    <inertial>
      <mass value="1.0" />
      <inertia ixx="0.5" ixy="0.0" ixz="0.0" iyy="0.5" iyz="0.0" izz="0.5" />
    </inertial>
  </link>

  <joint name="head_base_raise_joint_pitch" type="revolute">
    <origin rpy="0 0 0" xyz="0 0 0"/>
    <axis xyz="0 1 0"/>
    <limit effort="1000" lower="0.0" upper="0.449946" velocity="0.1"/>
    <parent link="head_base_raise_joint_z"/>
    <child link="head_base_raise_joint_pitch"/>
  </joint>

  <link name="head_joint_1">
    <visual>
      <geometry>
        <mesh filename="package://flintrobot_description/meshes/flint_neck1.stl"/>
      </geometry>
    </visual>
    <inertial>
      <mass value="1.0" />
      <inertia ixx="0.5" ixy="0.0" ixz="0.0" iyy="0.5" iyz="0.0" izz="0.5" />
    </inertial>
  </link>

  <joint name="head_joint_1" type="revolute">
    <origin rpy="0 0 0" xyz="0 0 0.0553"/>
    <axis xyz="0 0 1"/>
    <limit effort="1000" lower="-0.7854" upper="0.7854" velocity="0.1"/>
    <parent link="head_base_raise_joint_pitch"/>
    <child link="head_joint_1"/>
  </joint>

  <link name="head_joint_2">
    <visual>
      <geometry>
        <mesh filename="package://flintrobot_description/meshes/flint_neck2.stl"/>
      </geometry>
    </visual>
    <inertial>
      <mass value="1.0" />
      <inertia ixx="0.5" ixy="0.0" ixz="0.0" iyy="0.5" iyz="0.0" izz="0.5" />
    </inertial>
  </link>

  <joint name="head_joint_2" type="revolute">
    <origin rpy="0 0 0" xyz="-0.0016 0.018 0.0816"/>
    <axis xyz="0 1 0"/>
    <limit effort="1000" lower="-0.3491" upper="0.7854" velocity="0.1"/>
    <parent link="head_joint_1"/>
    <child link="head_joint_2"/>
  </joint>

  <link name="head">
    <visual>
      <geometry>
        <mesh filename="package://flintrobot_description/meshes/flint_head.stl"/>
      </geometry>
    </visual>
    <inertial>
      <mass value="1.0" />
      <inertia ixx="0.5" ixy="0.0" ixz="0.0" iyy="0.5" iyz="0.0" izz="0.5" />
    </inertial>
  </link>

  <joint name="head_joint_3" type="revolute">
    <origin rpy="0 0 0" xyz="-0.06887 -0.020278 0"/>
    <axis xyz="1 0 0"/>
    <limit effort="1000" lower="-0.3491" upper="0.3491" velocity="0.1"/>
    <parent link="head_joint_2"/>
    <child link="head"/>
  </joint>

  <joint name="head_joint_3b" type="fixed">
    <origin rpy="0 -0.1118756 0" xyz="0.11332 0.002304 0"/>
    <parent link="head"/>
    <child link="camera_base"/>
  </joint>

  <link name="camera_base">
    <visual>
      <geometry>
        <box size="0.02 0.18 0.02"/>
      </geometry>
      <origin rpy="0 0 0" xyz="0 0 0"/>
    </visual>
  </link>

  <link name="left_eye">
    <visual>
      <geometry>
        <cylinder length="0.02" radius="0.01"/>
      </geometry>
      <material name="green">
        <color rgba="0.0 1.0 0.0 1.0"/>
      </material>
      <origin rpy="0 1.5708 0" xyz="0.002 0.0 0.0"/>
    </visual>
  </link>

  <joint name="head_to_left_eye" type="fixed">
    <origin rpy="0 0 0" xyz="0.0 0.07103 0.0"/>
    <parent link="camera_base"/>
    <child link="left_eye"/>
  </joint>

  <link name="left_camera_optical_frame"/>
  <joint name="left_camera_optical_joint" type="fixed">
    <origin rpy="-1.5707963267948966 0.0 -1.5707963267948966" xyz="0 0 0"/>
    <parent link="left_eye"/>
    <child link="left_camera_optical_frame"/>
  </joint>

  <link name="right_eye">
    <visual>
      <geometry>
        <cylinder length="0.02" radius="0.01"/>
      </geometry>
      <material name="green">
        <color rgba="0.0 1.0 0.0 1.0"/>
      </material>
      <origin rpy="0 1.5708 0" xyz="0.002 0.0 0.0"/>
    </visual>
  </link>

  <joint name="head_to_right_eye" type="fixed">
    <origin rpy="0 0 0" xyz="0.0 -0.07103 0.0"/>
    <parent link="camera_base"/>
    <child link="right_eye"/>
  </joint>

  <link name="right_camera_optical_frame"/>
  <joint name="right_camera_optical_joint" type="fixed">
    <origin rpy="-1.5707963267948966 0.0 -1.5707963267948966" xyz="0 0 0"/>
    <parent link="right_eye"/>
    <child link="right_camera_optical_frame"/>
  </joint>

  <link name="right_shoulder_root"/>

  <joint name="right_shoulder_fixed_angle" type="fixed">
    <origin rpy="-0.17453 0 0" xyz="0.005 -0.13909 0.8815"/>
    <parent link="body_link"/>
    <child link="right_shoulder_root"/>
  </joint>

  <link name="right_shoulder">
    <visual>
      <geometry>
        <mesh filename="package://flintrobot_description/meshes/flint_joint1.stl"/>
      </geometry>
    </visual>
    <collision>
      <geometry>
        <cylinder length="0.076" radius="0.035"/>
      </geometry>
      <origin rpy="1.57075 0 0" xyz="0 -0.065 0"/>
    </collision>
  </link>

  <joint name="joint0" type="revolute">
    <axis xyz="0 1 0"/>
    <origin xyz="0 -0.0 0"/>
    <parent link="right_shoulder_root"/>
    <child link="right_shoulder"/>
    <limit effort="1000" lower="-3.1415926" upper="3.1415926" velocity="1.0"/>
  </joint>

  <link name="right_posterior_arm_root">
    <visual>
      <geometry>
        <mesh filename="package://flintrobot_description/meshes/flint_joint2.stl"/>
      </geometry>
    </visual>
    <inertial>
      <mass value="1.0" />
      <inertia ixx="0.5" ixy="0.0" ixz="0.0" iyy="0.5" iyz="0.0" izz="0.5" />
    </inertial>
  </link>

  <joint name="joint1" type="revolute">
    <axis xyz="1 0 0"/>
    <origin xyz="0.000294 -0.069 0"/>
    <parent link="right_shoulder"/>
    <child link="right_posterior_arm_root"/>
    <limit effort="1000" lower="-1.5708" upper="0.1745" velocity="1.0"/>
  </joint>

  <link name="right_posterior_arm">
    <visual>
      <geometry>
        <mesh filename="package://flintrobot_description/meshes/flint_joint3.stl"/>
      </geometry>
    </visual>
    <collision>
      <geometry>
        <cylinder length="0.23" radius="0.035"/>
      </geometry>
      <origin rpy="0 0 0" xyz="0 0 -0.06"/>
    </collision>
  </link>

  <joint name="joint2" type="revolute">
    <axis xyz="0 0 1"/>
    <origin xyz="-0.0001 0 -0.11197"/>
    <parent link="right_posterior_arm_root"/>
    <child link="right_posterior_arm"/>
    <limit effort="1000" lower="-3.1415926" upper="3.1415926" velocity="1.0"/>
  </joint>

  <link name="right_elbow">
    <visual>
      <geometry>
        <mesh filename="package://flintrobot_description/meshes/flint_joint4.stl"/>
      </geometry>
    </visual>
    <collision>
      <geometry>
        <box size="0.07 0.07 0.147"/>
      </geometry>
      <origin rpy="0 0 0" xyz="0 -0.03 -0.0735"/>
    </collision>
  </link>

  <joint name="joint3" type="revolute">
    <axis xyz="0 1 0"/>
    <origin xyz="0 0.02901 -0.198"/>
    <parent link="right_posterior_arm"/>
    <child link="right_elbow"/>
    <limit effort="1000" lower="-1.5708" upper="0.0" velocity="1.0"/>
  </joint>

  <link name="right_forearm_root">
    <visual>
      <geometry>
        <mesh filename="package://flintrobot_description/meshes/flint_joint5.stl"/>
      </geometry>
    </visual>
    <inertial>
      <mass value="1.0" />
      <inertia ixx="0.5" ixy="0.0" ixz="0.0" iyy="0.5" iyz="0.0" izz="0.5" />
    </inertial>
  </link>

  <joint name="joint4" type="revolute">
    <axis xyz="0 1 0"/>
    <origin xyz="0 -0.0555 -0.14721"/>
    <parent link="right_elbow"/>
    <child link="right_forearm_root"/>
    <limit effort="1000" lower="-1.5708" upper="0.0" velocity="1.0"/>
  </joint>

  <link name="right_forearm">
    <visual>
      <geometry>
        <mesh filename="package://flintrobot_description/meshes/flint_joint6.stl"/>
      </geometry>
    </visual>
    <collision>
      <geometry>
        <cylinder length="0.236" radius="0.035"/>
      </geometry>
      <origin rpy="0 0 0" xyz="0 0 -0.033"/>
    </collision>
  </link>

  <joint name="joint5" type="revolute">
    <axis xyz="0 0 1"/>
    <origin xyz="0 0.02768 -0.112"/>
    <parent link="right_forearm_root"/>
    <child link="right_forearm"/>
    <limit effort="1000" lower="-3.1415926" upper="3.1415926" velocity="1.0"/>
  </joint>

  <link name="right_forearm_b">
    <visual>
      <geometry>
        <mesh filename="package://flintrobot_description/meshes/flint_joint7.stl"/>
      </geometry>
    </visual>
    <collision>
      <geometry>
        <box size="0.07 0.07 0.05"/>
      </geometry>
      <origin rpy="0 0 0" xyz="0 0 0.005"/>
    </collision>
  </link>

  <joint name="joint6" type="revolute">
    <axis xyz="0 1 0"/>
    <origin xyz="0 0 -0.20252"/>
    <parent link="right_forearm"/>
    <child link="right_forearm_b"/>
    <limit effort="1000" lower="-0.5236" upper="0.5236" velocity="1.0"/>
  </joint>

  <link name="right_wrist">
    <visual>
      <geometry>
        <mesh filename="package://flintrobot_description/meshes/flint_joint8.stl"/>
      </geometry>
    </visual>
    <collision>
      <geometry>
        <box size="0.09 0.06 0.023"/>
      </geometry>
      <origin rpy="0 0 0" xyz="0.014 0 -0.0"/>
    </collision>
  </link>

  <joint name="joint7" type="revolute">
    <axis xyz="1 0 0"/>
    <origin xyz="-0.014 0 -0.04456"/>
    <parent link="right_forearm_b"/>
    <child link="right_wrist"/>
    <limit effort="1000" lower="-0.7854" upper="0.7854" velocity="1.0"/>
  </joint>

  <link name="right_grasp_center">
    <visual>
      <geometry>
        <box size="0.03 0.01 0.05"/>
      </geometry>
      <material name="green">
        <color rgba="0.0 1.0 0.0 1.0"/>
      </material>
      <origin rpy="0 0 0" xyz="0 0 0"/>
    </visual>
  </link>

  <joint name="right_wrists_to_grasp_center" type="fixed">
    <parent link="right_wrist"/>
    <child link="right_grasp_center"/>
    <origin rpy="0 1.5708 0" xyz="-0.02 0.055 -0.15"/>
  </joint>

  <link name="right_grasp_prepare_2">
    <visual>
      <geometry>
        <box size="0.03 0.01 0.05"/>
      </geometry>
      <material name="green">
        <color rgba="0.0 1.0 0.0 1.0"/>
      </material>
      <origin rpy="0 0 0" xyz="0 0 0"/>
    </visual>
  </link>

  <joint name="right_grasp_center_to_grasp_prepare_2" type="fixed">
    <parent link="right_grasp_center"/>
    <child link="right_grasp_prepare_2"/>
    <origin rpy="0 0 0" xyz="0.06 0.02 -0.01"/>
  </joint>

  <link name="right_grasp_prepare">
    <visual>
      <geometry>
        <box size="0.03 0.01 0.05"/>
      </geometry>
      <material name="green">
        <color rgba="0.0 1.0 0.0 1.0"/>
      </material>
      <origin rpy="0 0 0" xyz="0 0 0"/>
    </visual>
  </link>

  <joint name="right_grasp_center_to_grasp_prepare" type="fixed">
    <parent link="right_grasp_center"/>
    <child link="right_grasp_prepare"/>
    <origin rpy="0 0 0" xyz="0.12 0.04 -0.02"/>
  </joint>

  <link name="right_hand">
    <visual>
      <geometry>
        <mesh filename="package://flintrobot_description/meshes/flint_good_hand.stl"/>
      </geometry>
    </visual>
    <collision>
      <geometry>
        <box size="0.1 0.04 0.1"/>
      </geometry>
      <origin rpy="0 0 0" xyz="0 0 0.0"/>
    </collision>
  </link>

  <joint name="wrist_to_hand" type="fixed">
    <parent link="right_wrist"/>
    <child link="right_hand"/>
    <origin rpy="0 0 0" xyz="0.010324 -0.01302 -0.09651"/>
  </joint>

  <link name="right_hand_thumb_0">
    <visual>
      <geometry>
        <mesh filename="package://flintrobot_description/meshes/flint_hand_thumb_joint0.stl"/>
      </geometry>
    </visual>
    <inertial>
      <mass value="0.5" />
      <inertia ixx="0.5" ixy="0.0" ixz="0.0" iyy="0.5" iyz="0.0" izz="0.5" />
    </inertial>
  </link>

  <joint name="right_thumb_joint1" type="revolute">
    <parent link="right_wrist"/>
    <child link="right_hand_thumb_0"/>
    <axis xyz="0 0 1"/>
    <origin xyz="0.0408 0.01039 -0.0694"/>
    <limit effort="1000" lower="0" upper="2.0944" velocity="1.0"/>
  </joint>

  <link name="right_hand_thumb_1">
    <visual>
      <geometry>
        <mesh filename="package://flintrobot_description/meshes/flint_hand_thumb_joint1.stl"/>
      </geometry>
    </visual>
    <collision>
      <geometry>
        <box size="0.03 0.025 0.025"/>
      </geometry>
      <origin rpy="0 -0.0 0" xyz="0.03 0.013 -0.0"/>
    </collision>
    <inertial>
      <mass value="0.5" />
      <inertia ixx="0.5" ixy="0.0" ixz="0.0" iyy="0.5" iyz="0.0" izz="0.5" />
    </inertial>
  </link>

  <joint name="right_thumb_joint2" type="revolute">
    <parent link="right_hand_thumb_0"/>
    <child link="right_hand_thumb_1"/>
    <axis xyz="0 1 0"/>
    <origin xyz="0.010277 -0.01169 0.00121"/>
    <limit effort="1000" lower="0" upper="1.5708" velocity="1.0"/>
  </joint>

  <link name="right_hand_thumb_2">
    <visual>
      <geometry>
        <mesh filename="package://flintrobot_description/meshes/flint_hand_thumb_joint2.stl"/>
      </geometry>
    </visual>
    <collision>
      <geometry>
        <box size="0.02 0.02 0.02"/>
      </geometry>
      <origin rpy="0 0 0" xyz="0.008 0.01 0.003"/>
    </collision>
    <inertial>
      <mass value="0.5" />
      <inertia ixx="0.5" ixy="0.0" ixz="0.0" iyy="0.5" iyz="0.0" izz="0.5" />
    </inertial>
  </link>

  <joint name="right_thumb_joint3" type="revolute">
    <parent link="right_hand_thumb_1"/>
    <child link="right_hand_thumb_2"/>
    <axis xyz="0 1 0"/>
    <origin xyz="0.061119 0.002 -0.00337"/>
    <limit effort="1000" lower="0" upper="1.5708" velocity="1.0"/>
  </joint>

  <link name="right_hand_thumb_3">
    <visual>
      <geometry>
        <mesh filename="package://flintrobot_description/meshes/flint_hand_thumb_joint3.stl"/>
      </geometry>
    </visual>
    <collision>
      <geometry>
        <box size="0.02 0.02 0.01"/>
      </geometry>
      <origin rpy="0 0 0" xyz="0.025 0 0.008"/>
    </collision>
  </link>

  <joint name="right_thumb_joint4" type="revolute">
    <parent link="right_hand_thumb_2"/>
    <child link="right_hand_thumb_3"/>
    <axis xyz="0 1 0"/>
    <origin xyz="0.02197 0.01078 0.00108"/>
    <limit effort="1000" lower="0" upper="0.7854" velocity="1.0"/>
  </joint>

  <link name="right_finger1_root">
  </link>

  <joint name="wrists_to_finger1" type="fixed">
    <parent link="right_wrist"/>
    <child link="right_finger1_root"/>
    <origin rpy="0 -0.05236 0" xyz="0.047592 -0.01235 -0.164243"/>
  </joint>

  <link name="right_finger1_joint1">
    <visual>
      <geometry>
        <mesh filename="package://flintrobot_description/meshes/flint_hand_finger_joint0.stl"/>
      </geometry>
    </visual>
    <collision>
      <geometry>
        <box size="0.02 0.02 0.035"/>
      </geometry>
      <origin rpy="0 0 0" xyz="0 0 -0.012"/>
    </collision>
  </link>

  <joint name="right_finger1_joint1" type="revolute">
    <axis xyz="1 0 0"/>
    <parent link="right_finger1_root"/>
    <child link="right_finger1_joint1"/>
    <origin rpy="0 0 0" xyz="0 0 0"/>
    <limit effort="1000" lower="0" upper="1.5708" velocity="1.0"/>
  </joint>

  <link name="right_finger1_joint2">
    <visual>
      <geometry>
        <mesh filename="package://flintrobot_description/meshes/flint_hand_finger_joint1.stl"/>
      </geometry>
    </visual>
    <collision>
      <geometry>
        <box size="0.02 0.02 0.035"/>
      </geometry>
      <origin rpy="0 0 0" xyz="0 0 -0.032"/>
    </collision>
  </link>

  <joint name="right_finger1_joint2" type="revolute">
    <axis xyz="1 0 0"/>
    <parent link="right_finger1_joint1"/>
    <child link="right_finger1_joint2"/>
    <origin rpy="0 0 0" xyz="0.000017 0.0052 -0.030544"/>
    <limit effort="1000" lower="0" upper="1.5708" velocity="1.0"/>
  </joint>

  <link name="right_finger2_root">
  </link>

  <joint name="wrists_to_finger2" type="fixed">
    <parent link="right_wrist"/>
    <child link="right_finger2_root"/>
    <origin rpy="0 0 0" xyz="0.021945 -0.01231 -0.165475"/>
  </joint>

  <link name="right_finger2_joint1">
    <visual>
      <geometry>
        <mesh filename="package://flintrobot_description/meshes/flint_hand_finger_joint0.stl"/>
      </geometry>
    </visual>
    <collision>
      <geometry>
        <box size="0.02 0.02 0.035"/>
      </geometry>
      <origin rpy="0 0 0" xyz="0 0 -0.012"/>
    </collision>
  </link>

  <joint name="right_finger2_joint1" type="revolute">
    <axis xyz="1 0 0"/>
    <parent link="right_finger2_root"/>
    <child link="right_finger2_joint1"/>
    <origin rpy="0 0 0" xyz="0 0 0"/>
    <limit effort="1000" lower="0" upper="1.5708" velocity="1.0"/>
  </joint>

  <link name="right_finger2_joint2">
    <visual>
      <geometry>
        <mesh filename="package://flintrobot_description/meshes/flint_hand_finger_joint1.stl"/>
      </geometry>
    </visual>
    <collision>
      <geometry>
        <box size="0.02 0.02 0.035"/>
      </geometry>
      <origin rpy="0 0 0" xyz="0 0 -0.032"/>
    </collision>
  </link>

  <joint name="right_finger2_joint2" type="revolute">
    <axis xyz="1 0 0"/>
    <parent link="right_finger2_joint1"/>
    <child link="right_finger2_joint2"/>
    <origin rpy="0 0 0" xyz="0.000017 0.0052 -0.030544"/>
    <limit effort="1000" lower="0" upper="1.5708" velocity="1.0"/>
  </joint>

  <link name="right_finger3_root">
  </link>

  <joint name="wrists_to_finger3" type="fixed">
    <parent link="right_wrist"/>
    <child link="right_finger3_root"/>
    <origin rpy="0 0.05236 0" xyz="-0.003263 -0.01231 -0.165415"/>
  </joint>

  <link name="right_finger3_joint1">
    <visual>
      <geometry>
        <mesh filename="package://flintrobot_description/meshes/flint_hand_finger_joint0.stl"/>
      </geometry>
    </visual>
    <collision>
      <geometry>
        <box size="0.02 0.02 0.035"/>
      </geometry>
      <origin rpy="0 0 0" xyz="0 0 -0.012"/>
    </collision>
  </link>

  <joint name="right_finger3_joint1" type="revolute">
    <axis xyz="1 0 0"/>
    <parent link="right_finger3_root"/>
    <child link="right_finger3_joint1"/>
    <origin rpy="0 0 0" xyz="0 0 0"/>
    <limit effort="1000" lower="0" upper="1.5708" velocity="1.0"/>
  </joint>

  <link name="right_finger3_joint2">
    <visual>
      <geometry>
        <mesh filename="package://flintrobot_description/meshes/flint_hand_finger_joint1.stl"/>
      </geometry>
    </visual>
    <collision>
      <geometry>
        <box size="0.02 0.02 0.035"/>
      </geometry>
      <origin rpy="0 0 0" xyz="0 0 -0.032"/>
    </collision>
  </link>

  <joint name="right_finger3_joint2" type="revolute">
    <axis xyz="1 0 0"/>
    <parent link="right_finger3_joint1"/>
    <child link="right_finger3_joint2"/>
    <origin rpy="0 0 0" xyz="0.000017 0.0052 -0.030544"/>
    <limit effort="1000" lower="0" upper="1.5708" velocity="1.0"/>
  </joint>

  <link name="right_finger4_root">
  </link>

  <joint name="wrists_to_finger4" type="fixed">
    <parent link="right_wrist"/>
    <child link="right_finger4_root"/>
    <origin rpy="0 0.10472 0" xyz="-0.028492 -0.01231 -0.162315"/>
  </joint>

  <link name="right_finger4_joint1">
    <visual>
      <geometry>
        <mesh filename="package://flintrobot_description/meshes/flint_hand_finger_joint0.stl"/>
      </geometry>
    </visual>
    <collision>
      <geometry>
        <box size="0.02 0.02 0.035"/>
      </geometry>
      <origin rpy="0 0 0" xyz="0 0 -0.012"/>
    </collision>
  </link>

  <joint name="right_finger4_joint1" type="revolute">
    <axis xyz="1 0 0"/>
    <parent link="right_finger4_root"/>
    <child link="right_finger4_joint1"/>
    <origin rpy="0 0 0" xyz="0 0 0"/>
    <limit effort="1000" lower="0" upper="1.5708" velocity="1.0"/>
  </joint>

  <link name="right_finger4_joint2">
    <visual>
      <geometry>
        <mesh filename="package://flintrobot_description/meshes/flint_hand_finger_joint1.stl"/>
      </geometry>
    </visual>
    <collision>
      <geometry>
        <box size="0.02 0.02 0.035"/>
      </geometry>
      <origin rpy="0 0 0" xyz="0 0 -0.032"/>
    </collision>
  </link>

  <joint name="right_finger4_joint2" type="revolute">
    <axis xyz="1 0 0"/>
    <parent link="right_finger4_joint1"/>
    <child link="right_finger4_joint2"/>
    <origin rpy="0 0 0" xyz="0.000017 0.0052 -0.030544"/>
    <limit effort="1000" lower="0" upper="1.5708" velocity="1.0"/>
  </joint>

  <link name="left_shoulder_root"/>

  <joint name="left_shoulder_fixed_angle" type="fixed">
    <origin rpy="0.17453 0 0" xyz="0.005 0.13909 0.8815"/>
    <parent link="body_link"/>
    <child link="left_shoulder_root"/>
  </joint>

  <link name="left_shoulder">
    <visual>
      <geometry>
        <mesh filename="package://flintrobot_description/meshes/flint_joint1.stl" scale="1 -1 1"/>
      </geometry>
    </visual>
    <collision>
      <geometry>
        <cylinder length="0.076" radius="0.035"/>
      </geometry>
      <origin rpy="1.57075 0 0" xyz="0 0.065 0"/>
    </collision>
  </link>

  <joint name="joint0b" type="revolute">
    <axis xyz="0 1 0"/>
    <origin xyz="0 0 0"/>
    <parent link="left_shoulder_root"/>
    <child link="left_shoulder"/>
    <limit effort="1000" lower="-3.1415926" upper="3.1415926" velocity="1.0"/>
  </joint>

  <link name="left_posterior_arm_root">
    <visual>
      <geometry>
        <mesh filename="package://flintrobot_description/meshes/flint_joint2.stl" scale="1 -1 1"/>
      </geometry>
    </visual>
    <inertial>
      <mass value="1.0" />
      <inertia ixx="0.5" ixy="0.0" ixz="0.0" iyy="0.5" iyz="0.0" izz="0.5" />
    </inertial>
  </link>

  <joint name="joint1b" type="revolute">
    <axis xyz="1 0 0"/>
    <origin xyz="0.000294 0.069 0"/>
    <parent link="left_shoulder"/>
    <child link="left_posterior_arm_root"/>
    <limit effort="1000" lower="-0.1745" upper="1.5708" velocity="1.0"/>
  </joint>

  <link name="left_posterior_arm">
    <visual>
      <geometry>
        <mesh filename="package://flintrobot_description/meshes/flint_joint3.stl" scale="1 -1 1"/>
      </geometry>
    </visual>
    <collision>
      <geometry>
        <cylinder length="0.23" radius="0.035"/>
      </geometry>
      <origin rpy="0 0 0" xyz="0 0 -0.06"/>
    </collision>
  </link>

  <joint name="joint2b" type="revolute">
    <axis xyz="0 0 1"/>
    <origin xyz="-0.0001 0 -0.11197"/>
    <parent link="left_posterior_arm_root"/>
    <child link="left_posterior_arm"/>
    <limit effort="1000" lower="-3.1415926" upper="3.1415926" velocity="1.0"/>
  </joint>

  <link name="left_elbow">
    <visual>
      <geometry>
        <mesh filename="package://flintrobot_description/meshes/flint_joint4.stl" scale="1 -1 1"/>
      </geometry>
    </visual>
    <collision>
      <geometry>
        <box size="0.07 0.07 0.147"/>
      </geometry>
      <origin rpy="0 0 0" xyz="0 0.03 -0.0735"/>
    </collision>
  </link>

  <joint name="joint3b" type="revolute">
    <axis xyz="0 1 0"/>
    <origin xyz="0 -0.02901 -0.198"/>
    <parent link="left_posterior_arm"/>
    <child link="left_elbow"/>
    <limit effort="1000" lower="-1.5708" upper="0.0" velocity="1.0"/>
  </joint>

  <link name="left_forearm_root">
    <visual>
      <geometry>
        <mesh filename="package://flintrobot_description/meshes/flint_joint5.stl" scale="1 -1 1"/>
      </geometry>
    </visual>
    <inertial>
      <mass value="1.0" />
      <inertia ixx="0.5" ixy="0.0" ixz="0.0" iyy="0.5" iyz="0.0" izz="0.5" />
    </inertial>
  </link>

  <joint name="joint4b" type="revolute">
    <axis xyz="0 1 0"/>
    <origin xyz="0 0.0555 -0.14721"/>
    <parent link="left_elbow"/>
    <child link="left_forearm_root"/>
    <limit effort="1000" lower="-1.5708" upper="0.0" velocity="1.0"/>
  </joint>

  <link name="left_forearm">
    <visual>
      <geometry>
        <mesh filename="package://flintrobot_description/meshes/flint_joint6.stl" scale="1 -1 1"/>
      </geometry>
    </visual>
    <collision>
      <geometry>
        <cylinder length="0.236" radius="0.035"/>
      </geometry>
      <origin rpy="0 0 0" xyz="0 0 -0.033"/>
    </collision>
  </link>

  <joint name="joint5b" type="revolute">
    <axis xyz="0 0 1"/>
    <origin xyz="0 -0.02768 -0.112"/>
    <parent link="left_forearm_root"/>
    <child link="left_forearm"/>
    <limit effort="1000" lower="-3.1415926" upper="3.1415926" velocity="1.0"/>
  </joint>

  <link name="left_forearm_b">
    <visual>
      <geometry>
        <mesh filename="package://flintrobot_description/meshes/flint_joint7.stl" scale="1 -1 1"/>
      </geometry>
    </visual>
    <collision>
      <geometry>
        <box size="0.07 0.07 0.05"/>
      </geometry>
      <origin rpy="0 0 0" xyz="0 0 0.005"/>
    </collision>
  </link>

  <joint name="joint6b" type="revolute">
    <axis xyz="0 1 0"/>
    <origin xyz="0 0 -0.20252"/>
    <parent link="left_forearm"/>
    <child link="left_forearm_b"/>
    <limit effort="1000" lower="-0.5236" upper="0.5236" velocity="1.0"/>
  </joint>

  <link name="left_wrist">
    <visual>
      <geometry>
        <mesh filename="package://flintrobot_description/meshes/flint_joint8.stl" scale="1 -1 1"/>
      </geometry>
    </visual>
    <collision>
      <geometry>
        <box size="0.09 0.06 0.023"/>
      </geometry>
      <origin rpy="0 0 0" xyz="0.014 0 -0.0"/>
    </collision>
  </link>

  <joint name="joint7b" type="revolute">
    <axis xyz="1 0 0"/>
    <origin xyz="-0.014 0 -0.04456"/>
    <parent link="left_forearm_b"/>
    <child link="left_wrist"/>
    <limit effort="1000" lower="-0.7854" upper="0.7854" velocity="1.0"/>
  </joint>

  <link name="left_grasp_center">
    <visual>
      <geometry>
        <box size="0.03 0.01 0.05"/>
      </geometry>
      <material name="green">
        <color rgba="0.0 1.0 0.0 1.0"/>
      </material>
      <origin rpy="0 0 0" xyz="0 0 0"/>
    </visual>
  </link>

  <joint name="left_wrists_to_grasp_center" type="fixed">
    <parent link="left_wrist"/>
    <child link="left_grasp_center"/>
    <origin rpy="0 1.5708 0" xyz="-0.02 -0.055 -0.15"/>
  </joint>

  <link name="left_grasp_prepare_2">
    <visual>
      <geometry>
        <box size="0.03 0.01 0.05"/>
      </geometry>
      <material name="green">
        <color rgba="0.0 1.0 0.0 1.0"/>
      </material>
      <origin rpy="0 0 0" xyz="0 0 0"/>
    </visual>
  </link>

  <joint name="left_grasp_center_to_grasp_prepare_2" type="fixed">
    <parent link="left_grasp_center"/>
    <child link="left_grasp_prepare_2"/>
    <origin rpy="0 0 0" xyz="0.06 -0.02 -0.01"/>
  </joint>

  <link name="left_grasp_prepare">
    <visual>
      <geometry>
        <box size="0.03 0.01 0.05"/>
      </geometry>
      <material name="green">
        <color rgba="0.0 1.0 0.0 1.0"/>
      </material>
      <origin rpy="0 0 0" xyz="0 0 0"/>
    </visual>
  </link>

  <joint name="left_grasp_center_to_grasp_prepare" type="fixed">
    <parent link="left_grasp_center"/>
    <child link="left_grasp_prepare"/>
    <origin rpy="0 0 0" xyz="0.12 -0.04 -0.02"/>
  </joint>

  <link name="left_hand">
    <visual>
      <geometry>
        <mesh filename="package://flintrobot_description/meshes/flint_good_hand.stl" scale="1 -1 1"/>
      </geometry>
    </visual>
    <collision>
      <geometry>
        <box size="0.1 0.04 0.1"/>
      </geometry>
      <origin rpy="0 0 0" xyz="0 0 0.0"/>
    </collision>
  </link>

  <joint name="wrist_to_hand2" type="fixed">
    <parent link="left_wrist"/>
    <child link="left_hand"/>
    <origin rpy="0 0 0" xyz="0.010324 0.01302 -0.09651"/>
  </joint>

  <link name="left_hand_thumb_0">
    <visual>
      <geometry>
        <mesh filename="package://flintrobot_description/meshes/flint_hand_thumb_joint0.stl" scale="1 -1 1"/>
      </geometry>
    </visual>
    <inertial>
      <mass value="0.5" />
      <inertia ixx="0.5" ixy="0.0" ixz="0.0" iyy="0.5" iyz="0.0" izz="0.5" />
    </inertial>
  </link>

  <joint name="left_thumb_joint1" type="revolute">
    <parent link="left_wrist"/>
    <child link="left_hand_thumb_0"/>
    <axis xyz="0 0 1"/>
    <origin xyz="0.0408 -0.01039 -0.0694"/>
    <limit effort="1000" lower="-2.0944" upper="0" velocity="1.0"/>
  </joint>

  <link name="left_hand_thumb_1">
    <visual>
      <geometry>
        <mesh filename="package://flintrobot_description/meshes/flint_hand_thumb_joint1.stl" scale="1 -1 1"/>
      </geometry>
    </visual>
    <collision>
      <geometry>
        <box size="0.03 0.025 0.025"/>
      </geometry>
      <origin rpy="0 -0.0 0" xyz="0.03 -0.013 -0.0"/>
    </collision>
    <inertial>
      <mass value="0.5" />
      <inertia ixx="0.5" ixy="0.0" ixz="0.0" iyy="0.5" iyz="0.0" izz="0.5" />
    </inertial>
  </link>

  <joint name="left_thumb_joint2" type="revolute">
    <parent link="left_hand_thumb_0"/>
    <child link="left_hand_thumb_1"/>
    <axis xyz="0 1 0"/>
    <origin xyz="0.010277 0.01169 0.00121"/>
    <limit effort="1000" lower="0" upper="1.5708" velocity="1.0"/>
  </joint>

  <link name="left_hand_thumb_2">
    <visual>
      <geometry>
        <mesh filename="package://flintrobot_description/meshes/flint_hand_thumb_joint2.stl" scale="1 -1 1"/>
      </geometry>
    </visual>
    <collision>
      <geometry>
        <box size="0.02 0.02 0.02"/>
      </geometry>
      <origin rpy="0 0 0" xyz="0.008 -0.01 0.003"/>
    </collision>
  </link>

  <joint name="left_thumb_joint3" type="revolute">
    <parent link="left_hand_thumb_1"/>
    <child link="left_hand_thumb_2"/>
    <axis xyz="0 1 0"/>
    <origin xyz="0.061119 -0.002 -0.00337"/>
    <limit effort="1000" lower="0" upper="1.5708" velocity="1.0"/>
  </joint>

  <link name="left_hand_thumb_3">
    <visual>
      <geometry>
        <mesh filename="package://flintrobot_description/meshes/flint_hand_thumb_joint3.stl" scale="1 -1 1"/>
      </geometry>
    </visual>
    <collision>
      <geometry>
        <box size="0.02 0.02 0.01"/>
      </geometry>
      <origin rpy="0 0 0" xyz="0.025 0 0.008"/>
    </collision>
  </link>

  <joint name="left_thumb_joint4" type="revolute">
    <parent link="left_hand_thumb_2"/>
    <child link="left_hand_thumb_3"/>
    <axis xyz="0 1 0"/>
    <origin xyz="0.02197 -0.01078 0.00108"/>
    <limit effort="1000" lower="0.0" upper="0.7854" velocity="1.0"/>
  </joint>

  <link name="left_finger1_root">
  </link>

  <joint name="left_wrist_to_finger1" type="fixed">
    <parent link="left_wrist"/>
    <child link="left_finger1_root"/>
    <origin rpy="0 -0.05236 0" xyz="0.047592 0.01235 -0.164243"/>
  </joint>

  <link name="left_finger1_joint1">
    <visual>
      <geometry>
        <mesh filename="package://flintrobot_description/meshes/flint_hand_finger_joint0.stl" scale="1 -1 1"/>
      </geometry>
    </visual>
    <collision>
      <geometry>
        <box size="0.02 0.02 0.035"/>
      </geometry>
      <origin rpy="0 0 0" xyz="0 0 -0.012"/>
    </collision>
  </link>

  <joint name="left_finger1_joint1" type="revolute">
    <axis xyz="1 0 0"/>
    <parent link="left_finger1_root"/>
    <child link="left_finger1_joint1"/>
    <origin rpy="0 0 0" xyz="0 0 0"/>
    <limit effort="1000" lower="-1.5708" upper="0.0" velocity="1.0"/>
  </joint>

  <link name="left_finger1_joint2">
    <visual>
      <geometry>
        <mesh filename="package://flintrobot_description/meshes/flint_hand_finger_joint1.stl" scale="1 -1 1"/>
      </geometry>
    </visual>
    <collision>
      <geometry>
        <box size="0.02 0.02 0.035"/>
      </geometry>
      <origin rpy="0 0 0" xyz="0 0 -0.032"/>
    </collision>
  </link>

  <joint name="left_finger1_joint2" type="revolute">
    <axis xyz="1 0 0"/>
    <parent link="left_finger1_joint1"/>
    <child link="left_finger1_joint2"/>
    <origin rpy="0 0 0" xyz="0.000017 -0.0052 -0.030544"/>
    <limit effort="1000" lower="-1.5708" upper="0.0" velocity="1.0"/>
  </joint>

  <link name="left_finger2_root">
  </link>

  <joint name="left_wrists_to_finger2" type="fixed">
    <parent link="left_wrist"/>
    <child link="left_finger2_root"/>
    <origin rpy="0 0 0" xyz="0.021945 0.01231 -0.165475"/>
  </joint>

  <link name="left_finger2_joint1">
    <visual>
      <geometry>
        <mesh filename="package://flintrobot_description/meshes/flint_hand_finger_joint0.stl" scale="1 -1 1"/>
      </geometry>
    </visual>
    <collision>
      <geometry>
        <box size="0.02 0.02 0.035"/>
      </geometry>
      <origin rpy="0 0 0" xyz="0 0 -0.012"/>
    </collision>
  </link>

  <joint name="left_finger2_joint1" type="revolute">
    <axis xyz="1 0 0"/>
    <parent link="left_finger2_root"/>
    <child link="left_finger2_joint1"/>
    <origin rpy="0 0 0" xyz="0 0 0"/>
    <limit effort="1000" lower="-1.5708" upper="0.0" velocity="1.0"/>
  </joint>

  <link name="left_finger2_joint2">
    <visual>
      <geometry>
        <mesh filename="package://flintrobot_description/meshes/flint_hand_finger_joint1.stl" scale="1 -1 1"/>
      </geometry>
    </visual>
    <collision>
      <geometry>
        <box size="0.02 0.02 0.035"/>
      </geometry>
      <origin rpy="0 0 0" xyz="0 0 -0.032"/>
    </collision>
  </link>

  <joint name="left_finger2_joint2" type="revolute">
    <axis xyz="1 0 0"/>
    <parent link="left_finger2_joint1"/>
    <child link="left_finger2_joint2"/>
    <origin rpy="0 0 0" xyz="0.000017 -0.0052 -0.030544"/>
    <limit effort="1000" lower="-1.5708" upper="0.0" velocity="1.0"/>
  </joint>

  <link name="left_finger3_root">
  </link>

  <joint name="left_wrists_to_finger3" type="fixed">
    <parent link="left_wrist"/>
    <child link="left_finger3_root"/>
    <origin rpy="0 0.05236 0" xyz="-0.003263 0.01231 -0.165415"/>
  </joint>

  <link name="left_finger3_joint1">
    <visual>
      <geometry>
        <mesh filename="package://flintrobot_description/meshes/flint_hand_finger_joint0.stl" scale="1 -1 1"/>
      </geometry>
    </visual>
    <collision>
      <geometry>
        <box size="0.02 0.02 0.035"/>
      </geometry>
      <origin rpy="0 0 0" xyz="0 0 -0.012"/>
    </collision>
  </link>

  <joint name="left_finger3_joint1" type="revolute">
    <axis xyz="1 0 0"/>
    <parent link="left_finger3_root"/>
    <child link="left_finger3_joint1"/>
    <origin rpy="0 0 0" xyz="0 0 0"/>
    <limit effort="1000" lower="-1.5708" upper="0.0" velocity="1.0"/>
  </joint>

  <link name="left_finger3_joint2">
    <visual>
      <geometry>
        <mesh filename="package://flintrobot_description/meshes/flint_hand_finger_joint1.stl" scale="1 -1 1"/>
      </geometry>
    </visual>
    <collision>
      <geometry>
        <box size="0.02 0.02 0.035"/>
      </geometry>
      <origin rpy="0 0 0" xyz="0 0 -0.032"/>
    </collision>
  </link>

  <joint name="left_finger3_joint2" type="revolute">
    <axis xyz="1 0 0"/>
    <parent link="left_finger3_joint1"/>
    <child link="left_finger3_joint2"/>
    <origin rpy="0 0 0" xyz="0.000017 -0.0052 -0.030544"/>
    <limit effort="1000" lower="-1.5708" upper="0.0" velocity="1.0"/>
  </joint>

  <link name="left_finger4_root">
  </link>

  <joint name="left_wrists_to_finger4" type="fixed">
    <parent link="left_wrist"/>
    <child link="left_finger4_root"/>
    <origin rpy="0 0.10472 0" xyz="-0.028492 0.01231 -0.162315"/>
  </joint>

  <link name="left_finger4_joint1">
    <visual>
      <geometry>
        <mesh filename="package://flintrobot_description/meshes/flint_hand_finger_joint0.stl" scale="1 -1 1"/>
      </geometry>
    </visual>
    <collision>
      <geometry>
        <box size="0.02 0.02 0.035"/>
      </geometry>
      <origin rpy="0 0 0" xyz="0 0 -0.012"/>
    </collision>
  </link>

  <joint name="left_finger4_joint1" type="revolute">
    <axis xyz="1 0 0"/>
    <parent link="left_finger4_root"/>
    <child link="left_finger4_joint1"/>
    <origin rpy="0 0 0" xyz="0 0 0"/>
    <limit effort="1000" lower="-1.5708" upper="0.0" velocity="1.0"/>
  </joint>

  <link name="left_finger4_joint2">
    <visual>
      <geometry>
        <mesh filename="package://flintrobot_description/meshes/flint_hand_finger_joint1.stl" scale="1 -1 1"/>
      </geometry>
    </visual>
    <collision>
      <geometry>
        <box size="0.02 0.02 0.035"/>
      </geometry>
      <origin rpy="0 0 0" xyz="0 0 -0.032"/>
    </collision>
  </link>

  <joint name="left_finger4_joint2" type="revolute">
    <axis xyz="1 0 0"/>
    <parent link="left_finger4_joint1"/>
    <child link="left_finger4_joint2"/>
    <origin rpy="0 0 0" xyz="0.000017 -0.0052 -0.030544"/>
    <limit effort="1000" lower="-1.5708" upper="0.0" velocity="1.0"/>
  </joint>
  <mujoco>
    <compiler balanceinertia="true" discardvisual="false" meshdir="../meshes"/>
  </mujoco>
</robot>